<?xml version="1.0"?>
<robot name="pib">
  <link name="base_link"/>

  <joint name="base_link_to_base" type="fixed">
    <parent link="base_link"/>
    <child link="urdf_body"/>
    <origin rpy="0.0 0 0" xyz="0 0 -0.35"/>
  </joint>

  <link name="urdf_body">
    <visual>
      <origin xyz="-0.013132987582171207555 0.012566156500572068372 0.89118743593020444127" rpy="0 -0 0" />
      <geometry>
        <mesh filename="package://my_pib_description/meshes/urdf_body.stl"/>
      </geometry>
      <material name="urdf_body_material">
        <color rgba="0.90196078431372550543 0.90196078431372550543 0.90196078431372550543 1.0"/>
      </material>
    </visual>
    <collision>
      <origin xyz="-0.013132987582171207555 0.012566156500572068372 0.89118743593020444127" rpy="0 -0 0" />
      <geometry>
        <mesh filename="package://my_pib_description/meshes/urdf_body.stl"/>
      </geometry>
    </collision>
    <inertial>
      <origin xyz="-0.013148572994685497894 0.0062708327937176754074 0.3390600811380728441" rpy="0 0 0"/>
      <mass value="14.742451245988362984" />
      <inertia ixx="1.0215370085595509853" ixy="8.1750220923067520971e-07" ixz="2.0415306187995358275e-05" iyy="1.0802675023496579598" iyz="-0.0086376981174313364337" izz="0.10390259338508466003" />
    </inertial>
  </link>

  <link name="urdf_head_base">
    <visual>
      <origin xyz="0 1.7347234759768070944e-18 0.096600000000000019185" rpy="3.141592653589793116 -0 -5.2519588314391687104e-19" />
      <geometry>
        <mesh filename="package://my_pib_description/meshes/urdf_head_base.stl"/>
      </geometry>
      <material name="urdf_head_base_material">
        <color rgba="0.90196078431372550543 0.90196078431372550543 0.90196078431372550543 1.0"/>
      </material>
    </visual>
    <collision>
      <origin xyz="0 1.7347234759768070944e-18 0.096600000000000019185" rpy="3.141592653589793116 -0 -5.2519588314391687104e-19" />
      <geometry>
        <mesh filename="package://my_pib_description/meshes/urdf_head_base.stl"/>
      </geometry>
    </collision>
    <inertial>
      <origin xyz="-3.4780229255899585664e-05 0.017377672968967167177 -0.012899139977839313431" rpy="0 0 0"/>
      <mass value="0.2752183787437366691" />
      <inertia ixx="0.00026904306851896188585" ixy="4.9266012202656627337e-07" ixz="-1.9175035112766405392e-09" iyy="0.00016134789791135662157" iyz="-1.2039857658914160575e-08" izz="0.00039920756811286805697" />
    </inertial>
  </link>

  <link name="urdf_head">
    <visual>
      <origin xyz="0.048000000000000014877 0.10950000000000004174 -0.041750000000000002387" rpy="1.570796326794896558 1.570796326794896558 0" />
      <geometry>
        <mesh filename="package://my_pib_description/meshes/urdf_head.stl"/>
      </geometry>
      <material name="urdf_head_material">
        <color rgba="0.90196078431372550543 0.90196078431372550543 0.90196078431372550543 1.0"/>
      </material>
    </visual>
    <collision>
      <origin xyz="0.048000000000000014877 0.10950000000000004174 -0.041750000000000002387" rpy="1.570796326794896558 1.570796326794896558 0" />
      <geometry>
        <mesh filename="package://my_pib_description/meshes/urdf_head.stl"/>
      </geometry>
    </collision>
    <inertial>
      <origin xyz="-0.010752349739485883573 -0.069547124687647815522 -0.041747581920920449894" rpy="0 0 0"/>
      <mass value="0.51230822453493207735" />
      <inertia ixx="0.0045866170752479808875" ixy="0.00041100822612432741203" ixz="2.2896139325064005489e-06" iyy="0.003546183171123245409" iyz="5.7328545887266115502e-07" izz="0.0027748989212668900665" />
    </inertial>
  </link>

  <joint name="head_vertical" type="revolute">
    <origin xyz="-0.041250000000000008882 0.048000000000000021816 -0.012899999999999911537" rpy="1.570796326794896558 -2.7286008646779410258e-19 -1.5707963267948970021" />
    <parent link="urdf_head_base" />
    <child link="urdf_head" />
    <axis xyz="0 0 1"/>
    <limit effort="1" velocity="20" lower="-0.785398163397448279" upper="1.2217304763960306069"/>
    <joint_properties friction="0.0"/>
  </joint>

  <joint name="head_horizontal" type="revolute">
    <origin xyz="-0.013133585993821498758 0.012566127962098751214 0.98718743593020441551" rpy="3.141592653589793116 1.265248665445670253e-22 -0.0029026197161877579159" />
    <parent link="urdf_body" />
    <child link="urdf_head_base" />
    <axis xyz="0 0 1"/>
    <limit effort="1" velocity="20" lower="-1.570796326794896558" upper="1.570796326794896558"/>
    <joint_properties friction="0.0"/>
  </joint>

  <link name="urdf_shoulder_vertical_2">
    <visual>
      <origin xyz="-4.7531423241764514387e-16 1.1102230246251565404e-16 -0.0060000000000000053291" rpy="3.141592653589793116 -1.570796326794896558 0" />
      <geometry>
        <mesh filename="package://my_pib_description/meshes/urdf_shoulder_vertical.stl"/>
      </geometry>
      <material name="urdf_shoulder_vertical_material">
        <color rgba="0.90196078431372550543 0.90196078431372550543 0.90196078431372550543 1.0"/>
      </material>
    </visual>
    <collision>
      <origin xyz="-4.7531423241764514387e-16 1.1102230246251565404e-16 -0.0060000000000000053291" rpy="3.141592653589793116 -1.570796326794896558 0" />
      <geometry>
        <mesh filename="package://my_pib_description/meshes/urdf_shoulder_vertical.stl"/>
      </geometry>
    </collision>
    <inertial>
      <origin xyz="-4.7586038048089654607e-16 1.006971519153712357e-16 0.042642994191431304873" rpy="0 0 0"/>
      <mass value="0.25000000000000005551" />
      <inertia ixx="0.00072724079589201362679" ixy="-4.3924215229801008264e-76" ixz="5.7948769800549160682e-48" iyy="0.00047340124215038056074" iyz="1.2012875121614688988e-47" izz="0.00067680797638553576341" />
    </inertial>
  </link>

  <link name="urdf_shoulder_horizontal_2">
    <visual>
      <origin xyz="0 0.06500000000000000222 -0.037200000000000010836" rpy="1.570796326794896558 1.4791141973171533545e-31 -1.570796326794896558" />
      <geometry>
        <mesh filename="package://my_pib_description/meshes/urdf_shoulder_horizontal.stl"/>
      </geometry>
      <material name="urdf_shoulder_horizontal_material">
        <color rgba="0.90196078431372550543 0.90196078431372550543 0.90196078431372550543 1.0"/>
      </material>
    </visual>
    <collision>
      <origin xyz="0 0.06500000000000000222 -0.037200000000000010836" rpy="1.570796326794896558 1.4791141973171533545e-31 -1.570796326794896558" />
      <geometry>
        <mesh filename="package://my_pib_description/meshes/urdf_shoulder_horizontal.stl"/>
      </geometry>
    </collision>
    <inertial>
      <origin xyz="0.03141565709210976387 -1.2792556056129278375e-08 -0.037200000441739232426" rpy="0 0 0"/>
      <mass value="0.3499999999999999778" />
      <inertia ixx="0.00037058906386676219221" ixy="-1.2826983306073642213e-10" ixz="-7.7908665627271018081e-11" iyy="0.00079724647302412317024" iyz="1.2288090341174993695e-10" izz="0.00084576167306383361229" />
    </inertial>
  </link>

  <link name="urdf_elbow-upper_2">
    <visual>
      <origin xyz="-0.065000113126188405199 8.9579510664794526065e-07 0.14000000000000004108" rpy="-6.3221072019377880708e-31 -6.6980804052007131947e-31 -2.134136058872579744e-31" />
      <geometry>
        <mesh filename="package://my_pib_description/meshes/urdf_elbow-upper.stl"/>
      </geometry>
      <material name="urdf_elbow-upper_material">
        <color rgba="0.90196078431372550543 0.90196078431372550543 0.90196078431372550543 1.0"/>
      </material>
    </visual>
    <collision>
      <origin xyz="-0.065000113126188405199 8.9579510664794526065e-07 0.14000000000000004108" rpy="-6.3221072019377880708e-31 -6.6980804052007131947e-31 -2.134136058872579744e-31" />
      <geometry>
        <mesh filename="package://my_pib_description/meshes/urdf_elbow-upper.stl"/>
      </geometry>
    </collision>
    <inertial>
      <origin xyz="-4.4526328486782507099e-07 -0.005613683433376504342 -0.021290240894863005083" rpy="0 0 0"/>
      <mass value="0.21700098433583239754" />
      <inertia ixx="0.00020767324075755694561" ixy="-4.6362216441835536371e-10" ixz="-1.1291109162268427319e-09" iyy="0.0003257830855249441767" iyz="-2.9777665381350169389e-05" izz="0.00031634043511068947289" />
    </inertial>
  </link>

  <link name="urdf_elbow-lower_2">
    <visual>
      <origin xyz="-0.13812409200567404843 -0.16782384366109792673 0.027200113126188370238" rpy="2.356194490192344837 1.570796326794896558 0" />
      <geometry>
        <mesh filename="package://my_pib_description/meshes/urdf_elbow-lower.stl"/>
      </geometry>
      <material name="urdf_elbow-lower_material">
        <color rgba="0.90196078431372550543 0.90196078431372550543 0.90196078431372550543 1.0"/>
      </material>
    </visual>
    <collision>
      <origin xyz="-0.13812409200567404843 -0.16782384366109792673 0.027200113126188370238" rpy="2.356194490192344837 1.570796326794896558 0" />
      <geometry>
        <mesh filename="package://my_pib_description/meshes/urdf_elbow-lower.stl"/>
      </geometry>
    </collision>
    <inertial>
      <origin xyz="0.043032345513961067773 0.015369344989338893856 -0.037800343546969129849" rpy="0 0 0"/>
      <mass value="0.14960335360770107838" />
      <inertia ixx="0.00022936722111307664791" ixy="-5.4529749402997660957e-06" ixz="-4.34214950424493683e-09" iyy="0.00024909717114533216301" iyz="1.4345465837917941077e-09" izz="0.00016870950008625071694" />
    </inertial>
  </link>

  <link name="urdf_forearm_2">
    <visual>
      <origin xyz="-0.064741926567294535988 -0.00046870620534839035898 0.30343785999999994818" rpy="-1.8029589009935964194e-17 -3.1622885841323915255e-31 -1.0027142666266823121e-30" />
      <geometry>
        <mesh filename="package://my_pib_description/meshes/urdf_forearm.stl"/>
      </geometry>
      <material name="urdf_forearm_material">
        <color rgba="0.90196078431372550543 0.90196078431372550543 0.90196078431372550543 1.0"/>
      </material>
    </visual>
    <collision>
      <origin xyz="-0.064741926567294535988 -0.00046870620534839035898 0.30343785999999994818" rpy="-1.8029589009935964194e-17 -3.1622885841323915255e-31 -1.0027142666266823121e-30" />
      <geometry>
        <mesh filename="package://my_pib_description/meshes/urdf_forearm.stl"/>
      </geometry>
    </collision>
    <inertial>
      <origin xyz="0.0018761096199147314634 -4.4442311062226879472e-07 -0.050267094888194252533" rpy="0 0 0"/>
      <mass value="0.057000000000000022871" />
      <inertia ixx="0.00018119182777985410964" ixy="-2.057982129522934684e-10" ixz="7.3610097522744015404e-06" iyy="0.00017182225954469551869" iyz="-2.1213780996957606787e-09" izz="6.8995586508010533187e-05" />
    </inertial>
  </link>

  <joint name="forearm_right" type="revolute">
    <origin xyz="0.076438243046270615277 0.046739758236434170158 -0.037799999999999951694" rpy="0.7853981633974851384 -1.5707963267948850117 0" />
    <parent link="urdf_elbow-lower_2" />
    <child link="urdf_forearm_2" />
    <axis xyz="0 0 1"/>
    <limit effort="1" velocity="20" lower="-1.570796326794896558" upper="1.570796326794896558"/>
    <joint_properties friction="0.0"/>
  </joint>

  <joint name="elbow_right" type="revolute">
    <origin xyz="-0.037899999999999982314 -0.020999999999997687183 -0.076337859999996593441" rpy="-3.1415926535897926719 1.570796326794881681 0" />
    <parent link="urdf_elbow-upper_2" />
    <child link="urdf_elbow-lower_2" />
    <axis xyz="0 0 1"/>
    <limit effort="1" velocity="20" lower="-0.785398163397448279" upper="1.570796326794896558"/>
    <joint_properties friction="0.0"/>
  </joint>

  <joint name="upper_arm_right" type="revolute">
    <origin xyz="0.14000000000000023537 3.9898639947466563171e-17 -0.037200000000000787992" rpy="-1.5707963267948961139 5.2186995640945646394e-15 1.5707963267948894526" />
    <parent link="urdf_shoulder_horizontal_2" />
    <child link="urdf_elbow-upper_2" />
    <axis xyz="0 0 1"/>
    <limit effort="1" velocity="20" lower="-1.570796326794896558" upper="1.570796326794896558"/>
    <joint_properties friction="0.0"/>
  </joint>

  <joint name="shoulder_horizontal_right" type="revolute">
    <origin xyz="-6.4184768611141862493e-16 -0.037495364809999709443 0.059000000000000080158" rpy="1.5707963267948992225 -1.5707963267948956698 0" />
    <parent link="urdf_shoulder_vertical_2" />
    <child link="urdf_shoulder_horizontal_2" />
    <axis xyz="0 0 1"/>
    <limit effort="1" velocity="20" lower="-1.570796326794896558" upper="1.570796326794896558"/>
    <joint_properties friction="0.0"/>
  </joint>

  <joint name="shoulder_vertical_right" type="revolute">
    <origin xyz="-0.1731329875821712716 0.012565756136336734411 0.83568843836869388664" rpy="-1.570796326794896558 -0 1.570796326794896558" />
    <parent link="urdf_body" />
    <child link="urdf_shoulder_vertical_2" />
    <axis xyz="0 0 1"/>
    <limit effort="1" velocity="20" lower="-1.570796326794896558" upper="1.570796326794896558"/>
    <joint_properties friction="0.0"/>
  </joint>


</robot>
